Workbook

Sheet DCF
B1: FCFF Projection
C2: FY2026 | D2: FY2027 | E2: FY2028 | F2: FY2029 | G2: FY2030
B3: Operating profit (Estimates) | C3: 13195874 | D3: 14644927 | E3: 19088237 | F3: 20294000 | G3: 26303853
B4: Less Corporate tax | C4: =(C3*0.3) -> 3958762.2 | D4: =(D3*0.3) -> 4393478.1 | E4: =(E3*0.3) -> 5726471.1 | F4: =(F3*0.3) -> 6088200 | G4: =(G3*0.3) -> 7891155.9 | J4: CAPEX Estimations
B5: NOPAT | C5: =C3-C4 -> 9237111.8 | D5: =D3-D4 -> 10251449 | E5: =E3-E4 -> 13361766 | F5: =F3-F4 -> 14205800 | G5: =G3-G4 -> 18412697
B6: + D&A | C6: 5500000 | D6: 5800000 | E6: 6500000 | F6: 7500000 | G6: 8500000 | K6: FY2026 | L6: FY2027 | M6: FY2028 | N6: FY2029 | O6: FY2030
B7: Less Total Capex | C7: =(K9) -> 12000000 | D7: =(L9) -> 17040000 | E7: =(M9) -> 27081000 | F7: =(N9) -> 32122000 | G7: =(O9) -> 30165000 | J7: Sustaining capex | K7: 2000000 | L7: 2040000 | M7: 2081000 | N7: 2122000 | O7: 2165000
B8: ΔWC | D8: =L19 -> 349479.3 | E8: =M19 -> 750642.6 | F8: =N19 -> 475559 | G8: =O19 -> 1085828.6 | J8: New-project capex | K8: 10000000 | L8: 15000000 | M8: 25000000 | N8: 30000000 | O8: 28000000
B9: FCFF | C9: =C5+C6-C8-C7 -> 2737111.8 | D9: =D5+D6-D8-D7 -> -1338030.4 | E9: =E5+E6-E8-E7 -> -7969876.7 | F9: =F5+F6-F8-F7 -> -10891759 | G9: =G5+G6-G8-G7 -> -4338131.5 | J9: Total capex | K9: 12000000 | L9: 17040000 | M9: 27081000 | N9: 32122000 | O9: 30165000
B13: Discount Table
B14: FY | C14: Year | D14: FCFF | E14: Discount factor | F14: PV of FCFF | J14: Changes in Working Capital
B15: FY2026 | C15: 1 | D15: =C9 -> 2737111.8 | E15: =( 1 / ((1 + P27)^C15)) -> 0.84253096 | F15: =D15*E15 -> 2306101.4
B16: FY2027 | C16: 2 | D16: =D9 -> -1338030.4 | E16: =( 1 / ((1 + P27)^C16)) -> 0.70985842 | F16: =D16*E16 -> -949812.15 | K16: FY2026 | L16: FY2027 | M16: FY2028 | N16: FY2029 | O16: FY2030
B17: FY2028 | C17: 3 | D17: =E9 -> -7969876.7 | E17: =( 1 / ((1 + P27)^C17)) -> 0.5980777 | F17: =D17*E17 -> -4766605.5 | J17: Revenue | K17: 41341077 | L17: 44835870 | M17: 52342296 | N17: 57097886 | O17: 67956172
B18: FY2029 | C18: 4 | D18: =F9 -> -10891759 | E18: =( 1 / ((1 + P27)^C18)) -> 0.50389898 | F18: =D18*E18 -> -5488346.3 | J18: ΔRevenue | K18: - | L18: =L17-K17 -> 3494793 | M18: =M17-L17 -> 7506426 | N18: =N17-M17 -> 4755590 | O18: =O17-N17 -> 10858286
B19: FY2030 | C19: 5 | D19: =G9 -> -4338131.5 | E19: =( 1 / ((1 + P27)^C19)) -> 0.42455049 | F19: =D19*E19 -> -1841755.9 | J19: ΔWC (10%) | K19: - | L19: =L18*0.1 -> 349479.3 | M19: =M18*0.1 -> 750642.6 | N19: =N18*0.1 -> 475559 | O19: =O18*0.1 -> 1085828.6
B20: Subtotal | F20: =SUM(F15:F19) -> -10740418
B21: Terminal Value | D21: =P28 -> 78213227 | E21: =( 1 / ((1 + P27)^C19)) -> 0.42455049 | F21: =D21*E21 -> 33205464
B22: Enterprise Value | F22: =SUM(F20:F21) -> 22465046 | J22: Reinvestment rate
J23: Growth | L23: 0.04
J24: ROIC | L24: 0.1 | N24: Terminal Value
B25: Equity Value( Kes '000) | J25: Reinvestment rate | L25: =L23 / L24 -> 0.4 | N25: Normalized FCFF | P25: =L30 -> 11047618
B26: Enterprise Value | D26: =F22 -> 22465046 | N26: Growth(g) | P26: =L23 -> 0.04
B27: Net Cash | D27: =L48 -> 8477995 | J27: Normalized FCFF | N27: WACC | P27: 0.1869
B28: Equity value | D28: =SUM(D26:D27) -> 30943041 | J28: NOPAT FY2030 | L28: =G5 -> 18412697 | N28: Terminal Value | P28: =(P25*(1 + P26)) / (P27 - P26) -> 78213227
J29: Reinvestment rate | L29: =L25 -> 0.4
J30: Normalized FCFF | L30: =L28*(1 - L29 ) -> 11047618
B31: Share Value
B32: Shares to be Issued | D32: 18173299000
B33: Share Value | D33: =(D28 * 1000) / D32 -> 1.702665 | J33: WACC (KES '000)
J34: Equity Value | L34: 98394772
J35: Debt Value | L35: 3309520
J36: Capital value | L36: =L34+L35 -> 101704292
J37: Return on Equity | L37: 0.1919
J38: Return on Debt | L38: 0.0525
J39: Corporate Tax | L39: 0.3
J40: WACC | L40: =((L34 / L36) * L37) + ((L35 / L36) * L38 * (1 - L39) ) -> 0.18685132
J45: Net Cash( FY2025 )
J46: Cash and bank Balances | L46: 11787515
J47: Borrowings | L47: -3309520
...

Sheet Sensitivity Analysis
B2: Calculation Block
B3: Label | C3: Formula / Value
B4: WACC | C4: 0.1869
B5: Terminal growth (g) | C5: 0.04
B6: Terminal ROIC | C6: 0.1
B7: Reinvestment Rate | C7: =C5/C6 -> 0.4
B8: Normalized FCFF | C8: =DCF!G5*(1-C7) -> 11047618
B9: Terminal Value | C9: =(C8*(1+C5))/(C4-C5) -> 78213227
B10: PV of explicit FCFFs | C10: =DCF!C9/(1+C4)^1 + DCF!D9/(1+C4)^2 + DCF!E9/(1+C4)^3 + DCF!F9/(1+C4)^4 + DCF!G9/(1+C4)^5 -> -10740418
B11: PV of Terminal Value | C11: =C9/(1+C4)^5 -> 33205464
B12: Enterprise Value | C12: =SUM(C10:C11) -> 22465046
B13: Equity Value | C13: =C12+DCF!L48 -> 30943041
B14: Value per share | C14: =(C13*1000)/DCF!D32 -> 1.702665
B17: Sensitivity Table 1: WACC x Growth
C18: A | D18: B | E18: C | F18: D
B19: Growth ↓ / WACC → | C19: 0.14 | D19: 0.16 | E19: 0.1869 | F19: 0.2
B20: 0.03 | C20: =((DCF!$C$9/(1+C$19)^1 + DCF!$D$9/(1+C$19)^2 + DCF!$E$9/(1+C$19)^3 + DCF!$F$9/(1+C$19)^4 + DCF!$G$9/(1+C$19)^5) + ((DCF!$G$5*(1-$B20/$C$6)*(1+$B20)/(C$19-$B20))/(1+C$19)^5) + DCF!$L$48) * 1000 / DCF!$D$32 -> 3.2162046 | D20: =((DCF!$C$9/(1+D$19)^1 + DCF!$D$9/(1+D$19)^2 + DCF!$E$9/(1+D$19)^3 + DCF!$F$9/(1+D$19)^4 + DCF!$G$9/(1+D$19)^5) + ((DCF!$G$5*(1-$B20/$C$6)*(1+$B20)/(D$19-$B20))/(1+D$19)^5) + DCF!$L$48) * 1000 / DCF!$D$32 -> 2.4913952 | E20: =((DCF!$C$9/(1+E$19)^1 + DCF!$D$9/(1+E$19)^2 + DCF!$E$9/(1+E$19)^3 + DCF!$F$9/(1+E$19)^4 + DCF!$G$9/(1+E$19)^5) + ((DCF!$G$5*(1-$B20/$C$6)*(1+$B20)/(E$19-$B20))/(1+E$19)^5) + DCF!$L$48) * 1000 / DCF!$D$32 -> 1.852138 | F20: =((DCF!$C$9/(1+F$19)^1 + DCF!$D$9/(1+F$19)^2 + DCF!$E$9/(1+F$19)^3 + DCF!$F$9/(1+F$19)^4 + DCF!$G$9/(1+F$19)^5) + ((DCF!$G$5*(1-$B20/$C$6)*(1+$B20)/(F$19-$B20))/(1+F$19)^5) + DCF!$L$48) * 1000 / DCF!$D$32 -> 1.629026
B21: 0.04 | C21: =((DCF!$C$9/(1+C$19)^1 + DCF!$D$9/(1+C$19)^2 + DCF!$E$9/(1+C$19)^3 + DCF!$F$9/(1+C$19)^4 + DCF!$G$9/(1+C$19)^5) + ((DCF!$G$5*(1-$B21/$C$6)*(1+$B21)/(C$19-$B21))/(1+C$19)^5) + DCF!$L$48) * 1000 / DCF!$D$32 -> 3.0506875 | D21: =((DCF!$C$9/(1+D$19)^1 + DCF!$D$9/(1+D$19)^2 + DCF!$E$9/(1+D$19)^3 + DCF!$F$9/(1+D$19)^4 + DCF!$G$9/(1+D$19)^5) + ((DCF!$G$5*(1-$B21/$C$6)*(1+$B21)/(D$19-$B21))/(1+D$19)^5) + DCF!$L$48) * 1000 / DCF!$D$32 -> 2.3244158 | E21: =((DCF!$C$9/(1+E$19)^1 + DCF!$D$9/(1+E$19)^2 + DCF!$E$9/(1+E$19)^3 + DCF!$F$9/(1+E$19)^4 + DCF!$G$9/(1+E$19)^5) + ((DCF!$G$5*(1-$B21/$C$6)*(1+$B21)/(E$19-$B21))/(1+E$19)^5) + DCF!$L$48) * 1000 / DCF!$D$32 -> 1.702665 | F21: =((DCF!$C$9/(1+F$19)^1 + DCF!$D$9/(1+F$19)^2 + DCF!$E$9/(1+F$19)^3 + DCF!$F$9/(1+F$19)^4 + DCF!$G$9/(1+F$19)^5) + ((DCF!$G$5*(1-$B21/$C$6)*(1+$B21)/(F$19-$B21))/(1+F$19)^5) + DCF!$L$48) * 1000 / DCF!$D$32 -> 1.4901086
B22: 0.05 | C22: =((DCF!$C$9/(1+C$19)^1 + DCF!$D$9/(1+C$19)^2 + DCF!$E$9/(1+C$19)^3 + DCF!$F$9/(1+C$19)^4 + DCF!$G$9/(1+C$19)^5) + ((DCF!$G$5*(1-$B22/$C$6)*(1+$B22)/(C$19-$B22))/(1+C$19)^5) + DCF!$L$48) * 1000 / DCF!$D$32 -> 2.8366953 | D22: =((DCF!$C$9/(1+D$19)^1 + DCF!$D$9/(1+D$19)^2 + DCF!$E$9/(1+D$19)^3 + DCF!$F$9/(1+D$19)^4 + DCF!$G$9/(1+D$19)^5) + ((DCF!$G$5*(1-$B22/$C$6)*(1+$B22)/(D$19-$B22))/(1+D$19)^5) + DCF!$L$48) * 1000 / DCF!$D$32 -> 2.1183059 | E22: =((DCF!$C$9/(1+E$19)^1 + DCF!$D$9/(1+E$19)^2 + DCF!$E$9/(1+E$19)^3 + DCF!$F$9/(1+E$19)^4 + DCF!$G$9/(1+E$19)^5) + ((DCF!$G$5*(1-$B22/$C$6)*(1+$B22)/(E$19-$B22))/(1+E$19)^5) + DCF!$L$48) * 1000 / DCF!$D$32 -> 1.5250711 | F22: =((DCF!$C$9/(1+F$19)^1 + DCF!$D$9/(1+F$19)^2 + DCF!$E$9/(1+F$19)^3 + DCF!$F$9/(1+F$19)^4 + DCF!$G$9/(1+F$19)^5) + ((DCF!$G$5*(1-$B22/$C$6)*(1+$B22)/(F$19-$B22))/(1+F$19)^5) + DCF!$L$48) * 1000 / DCF!$D$32 -> 1.32724
B24: Sensitivity Table 2: WACC x Terminal ROIC
C25: A | D25: B | E25: C | F25: D
B26: ROIC ↓ / WACC → | C26: 0.14 | D26: 0.16 | E26: 0.1869 | F26: 0.2
B27: 0.1 | C27: =((DCF!$C$9/(1+C$26)^1 + DCF!$D$9/(1+C$26)^2 + DCF!$E$9/(1+C$26)^3 + DCF!$F$9/(1+C$26)^4 + DCF!$G$9/(1+C$26)^5) + ((DCF!$G$5*(1-$C$5/$B27)*(1+$C$5)/(C$26-$C$5))/(1+C$26)^5) + DCF!$L$48) * 1000 / DCF!$D$32 -> 3.0506875 | D27: =((DCF!$C$9/(1+D$26)^1 + DCF!$D$9/(1+D$26)^2 + DCF!$E$9/(1+D$26)^3 + DCF!$F$9/(1+D$26)^4 + DCF!$G$9/(1+D$26)^5) + ((DCF!$G$5*(1-$C$5/$B27)*(1+$C$5)/(D$26-$C$5))/(1+D$26)^5) + DCF!$L$48) * 1000 / DCF!$D$32 -> 2.3244158 | E27: =((DCF!$C$9/(1+E$26)^1 + DCF!$D$9/(1+E$26)^2 + DCF!$E$9/(1+E$26)^3 + DCF!$F$9/(1+E$26)^4 + DCF!$G$9/(1+E$26)^5) + ((DCF!$G$5*(1-$C$5/$B27)*(1+$C$5)/(E$26-$C$5))/(1+E$26)^5) + DCF!$L$48) * 1000 / DCF!$D$32 -> 1.702665 | F27: =((DCF!$C$9/(1+F$26)^1 + DCF!$D$9/(1+F$26)^2 + DCF!$E$9/(1+F$26)^3 + DCF!$F$9/(1+F$26)^4 + DCF!$G$9/(1+F$26)^5) + ((DCF!$G$5*(1-$C$5/$B27)*(1+$C$5)/(F$26-$C$5))/(1+F$26)^5) + DCF!$L$48) * 1000 / DCF!$D$32 -> 1.4901086
B28: 0.14 | C28: =((DCF!$C$9/(1+C$26)^1 + DCF!$D$9/(1+C$26)^2 + DCF!$E$9/(1+C$26)^3 + DCF!$F$9/(1+C$26)^4 + DCF!$G$9/(1+C$26)^5) + ((DCF!$G$5*(1-$C$5/$B28)*(1+$C$5)/(C$26-$C$5))/(1+C$26)^5) + DCF!$L$48) * 1000 / DCF!$D$32 -> 3.6761261 | D28: =((DCF!$C$9/(1+D$26)^1 + DCF!$D$9/(1+D$26)^2 + DCF!$E$9/(1+D$26)^3 + DCF!$F$9/(1+D$26)^4 + DCF!$G$9/(1+D$26)^5) + ((DCF!$G$5*(1-$C$5/$B28)*(1+$C$5)/(D$26-$C$5))/(1+D$26)^5) + DCF!$L$48) * 1000 / DCF!$D$32 -> 2.8022065 | E28: =((DCF!$C$9/(1+E$26)^1 + DCF!$D$9/(1+E$26)^2 + DCF!$E$9/(1+E$26)^3 + DCF!$F$9/(1+E$26)^4 + DCF!$G$9/(1+E$26)^5) + ((DCF!$G$5*(1-$C$5/$B28)*(1+$C$5)/(E$26-$C$5))/(1+E$26)^5) + DCF!$L$48) * 1000 / DCF!$D$32 -> 2.0506949 | F28: =((DCF!$C$9/(1+F$26)^1 + DCF!$D$9/(1+F$26)^2 + DCF!$E$9/(1+F$26)^3 + DCF!$F$9/(1+F$26)^4 + DCF!$G$9/(1+F$26)^5) + ((DCF!$G$5*(1-$C$5/$B28)*(1+$C$5)/(F$26-$C$5))/(1+F$26)^5) + DCF!$L$48) * 1000 / DCF!$D$32 -> 1.7925789
B29: 0.1869 | C29: =((DCF!$C$9/(1+C$26)^1 + DCF!$D$9/(1+C$26)^2 + DCF!$E$9/(1+C$26)^3 + DCF!$F$9/(1+C$26)^4 + DCF!$G$9/(1+C$26)^5) + ((DCF!$G$5*(1-$C$5/$B29)*(1+$C$5)/(C$26-$C$5))/(1+C$26)^5) + DCF!$L$48) * 1000 / DCF!$D$32 -> 4.0684892 | D29: =((DCF!$C$9/(1+D$26)^1 + DCF!$D$9/(1+D$26)^2 + DCF!$E$9/(1+D$26)^3 + DCF!$F$9/(1+D$26)^4 + DCF!$G$9/(1+D$26)^5) + ((DCF!$G$5*(1-$C$5/$B29)*(1+$C$5)/(D$26-$C$5))/(1+D$26)^5) + DCF!$L$48) * 1000 / DCF!$D$32 -> 3.1019442 | E29: =((DCF!$C$9/(1+E$26)^1 + DCF!$D$9/(1+E$26)^2 + DCF!$E$9/(1+E$26)^3 + DCF!$F$9/(1+E$26)^4 + DCF!$G$9/(1+E$26)^5) + ((DCF!$G$5*(1-$C$5/$B29)*(1+$C$5)/(E$26-$C$5))/(1+E$26)^5) + DCF!$L$48) * 1000 / DCF!$D$32 -> 2.2690282 | F29: =((DCF!$C$9/(1+F$26)^1 + DCF!$D$9/(1+F$26)^2 + DCF!$E$9/(1+F$26)^3 + DCF!$F$9/(1+F$26)^4 + DCF!$G$9/(1+F$26)^5) + ((DCF!$G$5*(1-$C$5/$B29)*(1+$C$5)/(F$26-$C$5))/(1+F$26)^5) + DCF!$L$48) * 1000 / DCF!$D$32 -> 1.9823309

Sheet Relative Valuation
B2: Peer Set
B3: Peer | F3: P/E | G3: EV/EBITDA
B4: TotalEnergies Marketing Kenya | F4: 12.98 | G4: 3.81
B5: Vivo Energy Mauritius | F5: 17.06 | G5: 11.09
B6: Umeme(Uganda) | F6: n/a | G6: 6.03
B7: Peer Median | F7: =SUM(F4:F5) / 2 -> 15.02 | G7: =SUM(G4:G6) / 3 -> 6.9766667
A10: Peer P/E Multiple to KPC | F10: Peer EV/EBITDA Multiple to KPC
A11: KPC FY2025 EPS | D11: 0.4112 | F11: KPC FY2025 EBITDA | I11: 0.4112
A12: Peer Median P/E | D12: =F7 -> 15.02 | F12: Peer Median EV/EBITDA | I12: =G7 -> 6.9766667
A13: Implied Share Value | D13: =D11*D12 -> 6.176224 | F13: Implied Enterprise Value | I13: 112121000000
A14: IPO Price | D14: 9 | F14: + Net Cash | I14: 8477995000
A15: Implied Downside | D15: =((D14 - D13)) / D14 -> 0.31375289 | F15: Implied Equity Value | I15: =SUM(I13:I14) -> 120598995000
F16: Shares Outstanding | I16: 18173299000
F17: Implied Share Value | I17: =I15 / I16 -> 6.6360541
F18: IPO Price | I18: 9
A19: Old Mutual P/E Multiple to KPC | F19: Implied Downside | I19: =((I18 - I17)) / I18 -> 0.26266066
A20: KPC FY2025 EPS | D20: 0.4112
A21: Peer Median P/E | D21: 11
A22: Implied Share Value | D22: =D20*D21 -> 4.5232 | F22: Summary of Relative Valuation
A23: IPO Price | D23: 9 | F23: Method | G23: Implied Value per Share | I23: vs IPO (KES 9.00)
A24: Implied Downside | D24: =((D23 - D22)) / D23 -> 0.49742222 | F24: P/E at peer median (15.0x) | G24: =D13 -> 6.176224 | I24: -0.31
F25: EV/EBITDA at peer median (6.03x) | G25: =I17 -> 6.6360541 | I25: -0.26
F26: P/E at Old Mutual target (11.0x) | G26: =D22 -> 4.5232 | I26: −50%
F27: Relative valuation range | G27: KES 4.53 – 6.64 | I27: −26% to −50%
N36: DCF Key Assumptions
N37: Input | O37: Value | P37: Source
N38: Risk-free rate | O38: 0.1264 | P38: Kenya 10-year bond, Jan 2026
N39: Beta | O39: 0.47 | P39: Bottom-up, oil/gas distribution
N40: Equity risk premium | O40: 0.1394 | P40: Damodaran, country-risk adjusted
N41: WACC | O41: 0.1869 | P41: Calculated
N42: Terminal growth | O42: 0.04 | P42: Conservative vs nominal GDP
N43: Terminal ROIC | O43: 0.1 | P43: Consistent with historical 9.3%

Sheet Football Field Chart
B2: Method | C2: Low (KES) | D2: High (KES) | E2: Midpoint (KES)
B3: DCF — base case | C3: 1.7 | D3: 1.7 | E3: 1.7
B4: DCF — sensitivity range | C4: 1.33 | D4: 3.65 | E4: 2.49
B5: Relative — P/E (peer median, 15.0x) | C5: 6.18 | D5: 6.18 | E5: 6.18
B6: Relative — EV/EBITDA (peer median, 6.03x) | C6: 6.64 | D6: 6.64 | E6: 6.64
B7: Relative — Old Mutual target P/E (11.0x) | C7: 4.53 | D7: 4.53 | E7: 4.53
B8: Independent analysts' range | C8: 4.61 | D8: 6.35 | E8: 5.48
B9: IPO offer price | C9: 9 | D9: 9 | E9: 9
